Workbook
Name INM: 'Tipo Projeto'!$D$3:INDEX('Tipo Projeto'!$D$3:$D$108,COUNTIF('Tipo Projeto'!$D$3:$D$108,"?*"))
Name Matriz_INM: 'Tipo Projeto'!$D$3:INDEX('Tipo Projeto'!$D$3:$D$108,COUNTIF('Tipo Projeto'!$D$3:$D$108,"?*"))
Name Matriz_UST: 'Tipo Projeto'!#REF!:INDEX('Tipo Projeto'!#REF!,COUNTIF('Tipo Projeto'!#REF!,"?*"))
Name PF_INM: 'AFP - INM'!$S$385
Name PF_UST: UST!$D$5
Name Tipo_Contagem: Resumo!$B$5
Name TipoProjeto: 'Tipo Projeto'!$A$3:INDEX('Tipo Projeto'!$A$3:$A$109,COUNTIF('Tipo Projeto'!$A$3:$A$109,"?*"))
Name TipoSistema: 'Tipo Sistema'!$A$2:$A$8
Name UST: 'Tipo Projeto'!#REF!

Sheet Instrução de Uso

Sheet Resumo
A1: Contagem de Pontos de Função
A3: Identificação
A4: O.S.: | B4: Premio IEL de Talentos | E4: Tipo de Atividade: | F4: Desenvolvimento ou Manutenção
A5: Tipo de Contagem: | B5: Detalhada | E5: Aplicação: | F5: Portal de Compras
A6: Empresa | B6: Premio IEL de Talentos / IEL Nacional
A7: Elaborador da contagem: | B7: Equipe de Métricas | E7: Data da Contagem: | F7: 44619
A8: Revisor da contagem: | B8: =IF($B$5="Detalhada",IF('AFP - Detalhada'!R5<>"",'AFP - Detalhada'!R5,""),IF($B$5="Estimativa",IF('AFP - Estimativa'!K5<>"",'AFP - Estimativa'!K5,""),IF($B$5="Indicativa",IF('AFP - Indicativa'!H5<>"",'AFP - Indicativa'!H5,""),""))) | E8: Data da Revisão: | F8: =IF($B$5="Detalhada",IF('AFP - Detalhada'!R6<>"",'AFP - Detalhada'!R6,""),IF($B$5="Estimativa",IF('AFP - Estimativa'!K6<>"",'AFP - Estimativa'!K6,""),IF($B$5="Indicativa",IF('AFP - Indicativa'!H6<>"",'AFP - Indicativa'!H6,""),"")))
A10: Propósito da Contagem
A11: =IF(Tipo_Contagem<>"","Obtenção do tamanho funcional (APF) "&IF(Tipo_Contagem="Estimativa","Estimado", IF(Tipo_Contagem="Indicativa", "Indicativo", "Detalhado"))&" das funcionalidades solicitadas/entregues na OS "&IF(B4<>"",B4,"em questão"),"") -> Obtenção do tamanho funcional (APF) Detalhado das funcionalidades solicitadas/entregues na OS Premio IEL de Talentos
A13: Escopo da Contagem
A16: Quadro Resumo | E16: Projeto de Desenvolvimento e Manutenção
A17: Arquivo Lógico Interno (ALI) | C17: =IF((IF($B$5="Detalhada",SUMIF('AFP - Detalhada'!$G$10:$G$192,"ALI",'AFP - Detalhada'!$S$10:$S$192),IF($B$5="Estimativa",SUMIF('AFP - Estimativa'!$G$10:$G$383,"ALI",'AFP - Estimativa'!$J$10:$J$383)*(1+'AFP - Estimativa'!$C$6),IF($B$5="Indicativa",SUMIF('AFP - Indicativa'!$F$10:$F$108,"ALI",'AFP - Indicativa'!$G$10:$G$108)*(1+'AFP - Indicativa'!$D$6))))),IF($B$5="Detalhada",SUMIF('AFP - Detalhada'!$G$10:$G$192,"ALI",'AFP - Detalhada'!$S$10:$S$192),IF($B$5="Estimativa",SUMIF('AFP - Estimativa'!$G$10:$G$383,"ALI",'AFP - Estimativa'!$J$10:$J$383)*(1+'AFP - Estimativa'!$C$6),IF($B$5="Indicativa",SUMIF('AFP - Indicativa'!$F$10:$F$108,"ALI",'AFP - Indicativa'!$G$10:$G$108)*(1+'AFP - Indicativa'!$D$6)))),"") -> 92.5 | E17: Distribuição de Esforço por Fase do Projeto (conforme item 6.2 do Anexo I-A do TR)
A18: Arquivo de Interface Externa (AIE) | C18: =IF((IF($B$5="Detalhada",SUMIF('AFP - Detalhada'!$G$10:$G$192,"AIE",'AFP - Detalhada'!$S$10:$S$192),IF($B$5="Estimativa",SUMIF('AFP - Estimativa'!$G$10:$G$383,"AIE",'AFP - Estimativa'!$J$10:$J$383)*(1+'AFP - Estimativa'!$C$6),IF($B$5="Indicativa",SUMIF('AFP - Indicativa'!$F$10:$F$108,"AIE",'AFP - Indicativa'!$G$10:$G$108)*(1+'AFP - Indicativa'!$D$6))))),(IF($B$5="Detalhada",SUMIF('AFP - Detalhada'!$G$10:$G$192,"AIE",'AFP - Detalhada'!$S$10:$S$192),IF($B$5="Estimativa",SUMIF('AFP - Estimativa'!$G$10:$G$383,"AIE",'AFP - Estimativa'!$J$10:$J$383)*(1+'AFP - Estimativa'!$C$6),IF($B$5="Indicativa",SUMIF('AFP - Indicativa'!$F$10:$F$108,"AIE",'AFP - Indicativa'!$G$10:$G$108)*(1+'AFP - Indicativa'!$D$6))))),"")
A19: Consulta Externa (CE) | C19: =IF($B$5="Detalhada",SUMIF('AFP - Detalhada'!$G$10:$G$192,"CE",'AFP - Detalhada'!$S$10:$S$192),IF($B$5="Estimativa",SUMIF('AFP - Estimativa'!$G$10:$G$383,"CE",'AFP - Estimativa'!$J$10:$J$383)*(1+'AFP - Estimativa'!$C$6),"")) -> 122.5 | E19: Refino | G19: 0.2
A20: Entrada Externa (EE) | C20: =IF($B$5="Detalhada",SUMIF('AFP - Detalhada'!$G$10:$G$192,"EE",'AFP - Detalhada'!$S$10:$S$192),IF($B$5="Estimativa",SUMIF('AFP - Estimativa'!$G$10:$G$383,"EE",'AFP - Estimativa'!$J$10:$J$383)*(1+'AFP - Estimativa'!$C$6),"")) -> 205 | E20: Implementação | G20: 0.6
A21: Saída Externa (SE) | C21: =IF($B$5="Detalhada",SUMIF('AFP - Detalhada'!$G$10:$G$192,"SE",'AFP - Detalhada'!$S$10:$S$192),IF($B$5="Estimativa",SUMIF('AFP - Estimativa'!$G$10:$G$383,"SE",'AFP - Estimativa'!$J$10:$J$383)*(1+'AFP - Estimativa'!$C$6),"")) -> 82.5
A22: INM | C22: =IF($B$5="Detalhada",SUMIF('AFP - Detalhada'!$G$10:$G$198,"INM",'AFP - Detalhada'!$S$10:$S$198),IF($B$5="Estimativa",SUMIF('AFP - Estimativa'!$G$10:$G$383,"INM",'AFP - Estimativa'!$J$10:$J$383)*(1+'AFP - Estimativa'!$C$6),"")) -> 0
A23: UST | C23: =UST!K404 -> 0
A24: Total (A) | C24: =SUM(C17:C23) -> 502.5 | E24: Teste | G24: 0.2
E25: Percentual de Esforço (E) | G25: =SUM(G19:G24) -> 1
A26: Projeto de Redocumentação de Requisitos
E27: =CONCATENATE("Quantidade Final (A) x ",IF(F4<>"",IF(F4="Desenvolvimento ou manutenção","(E1)","(E2)"),"")) -> Quantidade Final (A) x (E1) | G27: =C24*IF(F4<>"",IF(F4="Desenvolvimento ou manutenção",G25,C31),0) -> 502.5
A28: Distribuição de Esforço conforme item 4.11 do SISP | E28: Fator de criticidade | G28: 1
E29: Quantidade Final Ajustada | G29: =G27*G28 -> 502.5
A30: Redocumentação somente requisitos | C30: 0.2
A31: Percentual de Esforço (E2) | C31: =SUM(C30:C30) -> 0.2

Sheet AFP - Detalhada
C1: Contagem de Pontos de Função Contagem Detalhada
J3: Elaborador da contagem: | R3: Andro Márcio Correa Louredo | W3: Validação/Controle de Divergência Fábrica de Métricas/Cliente | Z3: Elaborador da contagem:
B4: Contagem de PF Bruto: | D4: =R193 -> 647 | E4: Situação: | F4: Percentual de Divergência: | J4: Data da Contagem: | R4: 44717 | Z4: Data da Contagem:
B5: Contagem Fábrica de Software: | D5: =$S$193 -> 502.5 | E5: =IF(D6=0,"",IF(D5<>D6,"Em Divergência","Concluído")) | F5: =IF(ISERROR(1-(D6)/(D5)),"0",1-(D6)/(D5)) -> 1 | J5: Revisor da contagem: | Z5: Revisor da contagem:
B6: Contagem Fábrica de Métricas: | D6: =$AJ$193 -> 0 | J6: Data da Revisão: | Z6: Data da Revisão:
B8: Tipo Projeto | C8: Fator Ajuste | D8: Módulo | E8: Requisito | F8: Processos elementares | G8: Tipo | H8: Qtd. INM | I8: TD / DER | K8: RLR / ALR | O8: Complexidade | R8: PFB | S8: PFL | T8: Insumo | U8: Observação | W8: Validação | X8: Tipo Projeto | Y8: Fator Ajuste | Z8: Tipo | AA8: TD / DER | AC8: RLR / ALR | AG8: Complexidade | AJ8: PF | AK8: Parecer Técnico | AM8: Resposta Fábrica de Software | AO8: Parecer Final | AP8: Validação Final
I9: Qtd. | J9: Descrição | K9: Qtd. | L9: Descrição | M9: C_T | N9: C_D | P9: PF_T | Q9: PF_D | AA9: Qtd. | AB9: Descrição | AC9: Qtd. | AD9: Descrição | AE9: C_T | AF9: C_D | AH9: PF_T | AI9: PF_D
B10: Guia de Métricas da STI - Aplicação/Desenvolvimento | C10: =IF(B10<>"",VLOOKUP(B10,'Tipo Projeto'!$A$3:$B$44,2,0),0) -> 1 | D10: Usuário | F10: Pesquisar Usuários | G10: CE | I10: 10 | J10: Entidade Perfil Nome Login Email Situação Data Cadastro Data Atualização Ação Mensagem | K10: 1 | L10: Usuário | M10: =IF(G10="EE",IF(OR(AND(OR(K10=1,K10=0),I10>0,I10<5),AND(OR(K10=1,K10=0),I10>4,I10<16),AND(K10=2,I10>0,I10<5)),"Simples",IF(OR(AND(OR(K10=1,K10=0),I10>15),AND(K10=2,I10>4,I10<16),AND(K10>2,I10>0,I10<5)),"Médio",IF(OR(AND(K10=2,I10>15),AND(K10>2,I10>4,I10<16),AND(K10>2,I10>15)),"Complexo",""))), IF(OR(G10="CE",G10="SE"),IF(OR(AND(OR(K10=1,K10=0),I10>0,I10<6),AND(OR(K10=1,K10=0),I10>5,I10<20),AND(K10>1,K10<4,I10>0,I10<6)),"Simples",IF(OR(AND(OR(K10=1,K10=0),I10>19),AND(K10>1,K10<4,I10>5,I10<20),AND(K10>3,I10>0,I10<6)),"Médio",IF(OR(AND(K10>1,K10<4,I10>19),AND(K10>3,I10>5,I10<20),AND(K10>3,I10>19)),"Complexo",""))),"")) -> Simples | N10: =IF(G10="ALI",IF(OR(AND(OR(K10=1,K10=0),I10>0,I10<20),AND(OR(K10=1,K10=0),I10>19,I10<51),AND(K10>1,K10<6,I10>0,I10<20)),"Simples",IF(OR(AND(OR(K10=1,K10=0),I10>50),AND(K10>1,K10<6,I10>19,I10<51),AND(K10>5,I10>0,I10<20)),"Médio",IF(OR(AND(K10>1,K10<6,I10>50),AND(K10>5,I10>19,I10<51),AND(K10>5,I10>50)),"Complexo",""))), IF(G10="AIE",IF(OR(AND(OR(K10=1, K10=0),I10>0,I10<20),AND(OR(K10=1, K10=0),I10>19,I10<51),AND(K10>1,K10<6,I10>0,I10<20)),"Simples",IF(OR(AND(OR(K10=1, K10=0),I10>50),AND(K10>1,K10<6,I10>19,I10<51),AND(K10>5,I10>0,I10<20)),"Médio",IF(OR(AND(K10>1,K10<6,I10>50),AND(K10>5,I10>19,I10<51),AND(K10>5,I10>50)),"Complexo",""))),"")) | O10: =IF(M10="",N10,IF(N10="",M10,"")) -> Simples | P10: =IF(AND(OR(G10="EE",G10="CE"),O10="Simples"),3, IF(AND(OR(G10="EE",G10="CE"),O10="Médio"),4, IF(AND(OR(G10="EE",G10="CE"),O10="Complexo"),6, IF(AND(G10="SE",O10="Simples"),4, IF(AND(G10="SE",O10="Médio"),5, IF(AND(G10="SE",O10="Complexo"),7,0)))))) -> 3 | Q10: =IF(AND(G10="ALI",N10="Simples"),7, IF(AND(G10="ALI",N10="Médio"),10, IF(AND(G10="ALI",N10="Complexo"),15, IF(AND(G10="AIE",N10="Simples"),5, IF(AND(G10="AIE",N10="Médio"),7, IF(AND(G10="AIE",N10="Complexo"),10,0)))))) -> 0 | R10: =IF(G10="INM",C10*H10,IF(AND(OR(G10="EE",G10="CE"),O10="Simples"),3, IF(AND(OR(G10="EE",G10="CE"),O10="Médio"),4, IF(AND(OR(G10="EE",G10="CE"),O10="Complexo"),6, IF(AND(G10="SE",O10="Simples"),4, IF(AND(G10="SE",O10="Médio"),5, IF(AND(G10="SE",O10="Complexo"),7, IF(AND(G10="ALI",O10="Médio"),10, IF(AND(G10="ALI",O10="Simples"),7, IF(AND(G10="ALI",O10="Complexo"),15, IF(AND(G10="AIE",O10="Simples"),5, IF(AND(G10="AIE",O10="Médio"),7, IF(AND(G10="AIE",O10="Complexo"),10,0)) ))))))))))) -> 3 | S10: =IF(G10="INM",C10*H10,IF(B10<>"Manutenção em interface",IF(B10<>"Desenv., Manutenção e Publicação de Páginas Estáticas",(P10+Q10)*C10,C10),C10)) -> 3 | T10: PDTIC25093-2 | Y10: =IF(X10<>"",VLOOKUP(X10,'Tipo Projeto'!$A$3:$B$44,2,0),0) -> 0 | AE10: =IF(Z10="EE",IF(OR(AND(OR(AC10=1,AC10=0),AA10>0,AA10<5),AND(OR(AC10=1,AC10=0),AA10>4,AA10<16),AND(AC10=2,AA10>0,AA10<5)),"Simples",IF(OR(AND(OR(AC10=1,AC10=0),AA10>15),AND(AC10=2,AA10>4,AA10<16),AND(AC10>2,AA10>0,AA10<5)),"Médio",IF(OR(AND(AC10=2,AA10>15),AND(AC10>2,AA10>4,AA10<16),AND(AC10>2,AA10>15)),"Complexo",""))), IF(OR(Z10="CE",Z10="SE"),IF(OR(AND(OR(AC10=1,AC10=0),AA10>0,AA10<6),AND(OR(AC10=1,AC10=0),AA10>5,AA10<20),AND(AC10>1,AC10<4,AA10>0,AA10<6)),"Simples",IF(OR(AND(OR(AC10=1,AC10=0),AA10>19),AND(AC10>1,AC10<4,AA10>5,AA10<20),AND(AC10>3,AA10>0,AA10<6)),"Médio",IF(OR(AND(AC10>1,AC10<4,AA10>19),AND(AC10>3,AA10>5,AA10<20),AND(AC10>3,AA10>19)),"Complexo",""))),"")) | AF10: =IF(Z10="ALI",IF(OR(AND(OR(AC10=1,AC10=0),AA10>0,AA10<20),AND(OR(AC10=1,AC10=0),AA10>19,AA10<51),AND(AC10>1,AC10<6,AA10>0,AA10<20)),"Simples",IF(OR(AND(OR(AC10=1,AC10=0),AA10>50),AND(AC10>1,AC10<6,AA10>19,AA10<51),AND(AC10>5,AA10>0,AA10<20)),"Médio",IF(OR(AND(AC10>1,AC10<6,AA10>50),AND(AC10>5,AA10>19,AA10<51),AND(AC10>5,AA10>50)),"Complexo",""))), IF(Z10="AIE",IF(OR(AND(OR(AC10=1, AC10=0),AA10>0,AA10<20),AND(OR(AC10=1, AC10=0),AA10>19,AA10<51),AND(AC10>1,AC10<6,AA10>0,AA10<20)),"Simples",IF(OR(AND(OR(AC10=1, AC10=0),AA10>50),AND(AC10>1,AC10<6,AA10>19,AA10<51),AND(AC10>5,AA10>0,AA10<20)),"Médio",IF(OR(AND(AC10>1,AC10<6,AA10>50),AND(AC10>5,AA10>19,AA10<51),AND(AC10>5,AA10>50)),"Complexo",""))),"")) | AG10: =IF(AE10="",AF10,IF(AF10="",AE10,"")) | AH10: =IF(AND(OR(Z10="EE",Z10="CE"),AG10="Simples"),3, IF(AND(OR(Z10="EE",Z10="CE"),AG10="Médio"),4, IF(AND(OR(Z10="EE",Z10="CE"),AG10="Complexo"),6, IF(AND(Z10="SE",AG10="Simples"),4, IF(AND(Z10="SE",AG10="Médio"),5, IF(AND(Z10="SE",AG10="Complexo"),7,0)))))) -> 0 | AI10: =IF(AND(Z10="ALI",AF10="Simples"),7, IF(AND(Z10="ALI",AF10="Médio"),10, IF(AND(Z10="ALI",AF10="Complexo"),15, IF(AND(Z10="AIE",AF10="Simples"),5, IF(AND(Z10="AIE",AF10="Médio"),7, IF(AND(Z10="AIE",AF10="Complexo"),10,0)))))) -> 0 | AJ10: =IF(W10="OK",S10,( IF(X10<>"Manutenção em interface",IF(X10<>"Desenv., Manutenção e Publicação de Páginas Estáticas",(AH10+AI10)*Y10,Y10),Y10))) -> 0 | AP10: =IF(AJ10=0,"",IF(AJ10=S10,"OK","Divergente"))
B11: Guia de Métricas da STI - Aplicação/Desenvolvimento | C11: =IF(B11<>"",VLOOKUP(B11,'Tipo Projeto'!$A$3:$B$44,2,0),0) -> 1 | D11: Usuário | E11: HU-020_Cadastrar_Admin_Regionais.docx | F11: Incluir Usuário | G11: EE | I11: 12 | J11: Login Nome CPF Telefone Celular Email Cargo Perfil UF Atuação Entidade Ação Mensagem | K11: 1 | L11: Usuário | M11: =IF(G11="EE",IF(OR(AND(OR(K11=1,K11=0),I11>0,I11<5),AND(OR(K11=1,K11=0),I11>4,I11<16),AND(K11=2,I11>0,I11<5)),"Simples",IF(OR(AND(OR(K11=1,K11=0),I11>15),AND(K11=2,I11>4,I11<16),AND(K11>2,I11>0,I11<5)),"Médio",IF(OR(AND(K11=2,I11>15),AND(K11>2,I11>4,I11<16),AND(K11>2,I11>15)),"Complexo",""))), IF(OR(G11="CE",G11="SE"),IF(OR(AND(OR(K11=1,K11=0),I11>0,I11<6),AND(OR(K11=1,K11=0),I11>5,I11<20),AND(K11>1,K11<4,I11>0,I11<6)),"Simples",IF(OR(AND(OR(K11=1,K11=0),I11>19),AND(K11>1,K11<4,I11>5,I11<20),AND(K11>3,I11>0,I11<6)),"Médio",IF(OR(AND(K11>1,K11<4,I11>19),AND(K11>3,I11>5,I11<20),AND(K11>3,I11>19)),"Complexo",""))),"")) -> Simples | N11: =IF(G11="ALI",IF(OR(AND(OR(K11=1,K11=0),I11>0,I11<20),AND(OR(K11=1,K11=0),I11>19,I11<51),AND(K11>1,K11<6,I11>0,I11<20)),"Simples",IF(OR(AND(OR(K11=1,K11=0),I11>50),AND(K11>1,K11<6,I11>19,I11<51),AND(K11>5,I11>0,I11<20)),"Médio",IF(OR(AND(K11>1,K11<6,I11>50),AND(K11>5,I11>19,I11<51),AND(K11>5,I11>50)),"Complexo",""))), IF(G11="AIE",IF(OR(AND(OR(K11=1, K11=0),I11>0,I11<20),AND(OR(K11=1, K11=0),I11>19,I11<51),AND(K11>1,K11<6,I11>0,I11<20)),"Simples",IF(OR(AND(OR(K11=1, K11=0),I11>50),AND(K11>1,K11<6,I11>19,I11<51),AND(K11>5,I11>0,I11<20)),"Médio",IF(OR(AND(K11>1,K11<6,I11>50),AND(K11>5,I11>19,I11<51),AND(K11>5,I11>50)),"Complexo",""))),"")) | O11: =IF(M11="",N11,IF(N11="",M11,"")) -> Simples | P11: =IF(AND(OR(G11="EE",G11="CE"),O11="Simples"),3, IF(AND(OR(G11="EE",G11="CE"),O11="Médio"),4, IF(AND(OR(G11="EE",G11="CE"),O11="Complexo"),6, IF(AND(G11="SE",O11="Simples"),4, IF(AND(G11="SE",O11="Médio"),5, IF(AND(G11="SE",O11="Complexo"),7,0)))))) -> 3 | Q11: =IF(AND(G11="ALI",N11="Simples"),7, IF(AND(G11="ALI",N11="Médio"),10, IF(AND(G11="ALI",N11="Complexo"),15, IF(AND(G11="AIE",N11="Simples"),5, IF(AND(G11="AIE",N11="Médio"),7, IF(AND(G11="AIE",N11="Complexo"),10,0)))))) -> 0 | R11: =IF(G11="INM",C11*H11,IF(AND(OR(G11="EE",G11="CE"),O11="Simples"),3, IF(AND(OR(G11="EE",G11="CE"),O11="Médio"),4, IF(AND(OR(G11="EE",G11="CE"),O11="Complexo"),6, IF(AND(G11="SE",O11="Simples"),4, IF(AND(G11="SE",O11="Médio"),5, IF(AND(G11="SE",O11="Complexo"),7, IF(AND(G11="ALI",O11="Médio"),10, IF(AND(G11="ALI",O11="Simples"),7, IF(AND(G11="ALI",O11="Complexo"),15, IF(AND(G11="AIE",O11="Simples"),5, IF(AND(G11="AIE",O11="Médio"),7, IF(AND(G11="AIE",O11="Complexo"),10,0)) ))))))))))) -> 3 | S11: =IF(G11="INM",C11*H11,IF(B11<>"Manutenção em interface",IF(B11<>"Desenv., Manutenção e Publicação de Páginas Estáticas",(P11+Q11)*C11,C11),C11)) -> 3 | T11: 20 | Y11: =IF(X11<>"",VLOOKUP(X11,'Tipo Projeto'!$A$3:$B$44,2,0),0) -> 0 | AE11: =IF(Z11="EE",IF(OR(AND(OR(AC11=1,AC11=0),AA11>0,AA11<5),AND(OR(AC11=1,AC11=0),AA11>4,AA11<16),AND(AC11=2,AA11>0,AA11<5)),"Simples",IF(OR(AND(OR(AC11=1,AC11=0),AA11>15),AND(AC11=2,AA11>4,AA11<16),AND(AC11>2,AA11>0,AA11<5)),"Médio",IF(OR(AND(AC11=2,AA11>15),AND(AC11>2,AA11>4,AA11<16),AND(AC11>2,AA11>15)),"Complexo",""))), IF(OR(Z11="CE",Z11="SE"),IF(OR(AND(OR(AC11=1,AC11=0),AA11>0,AA11<6),AND(OR(AC11=1,AC11=0),AA11>5,AA11<20),AND(AC11>1,AC11<4,AA11>0,AA11<6)),"Simples",IF(OR(AND(OR(AC11=1,AC11=0),AA11>19),AND(AC11>1,AC11<4,AA11>5,AA11<20),AND(AC11>3,AA11>0,AA11<6)),"Médio",IF(OR(AND(AC11>1,AC11<4,AA11>19),AND(AC11>3,AA11>5,AA11<20),AND(AC11>3,AA11>19)),"Complexo",""))),"")) | AF11: =IF(Z11="ALI",IF(OR(AND(OR(AC11=1,AC11=0),AA11>0,AA11<20),AND(OR(AC11=1,AC11=0),AA11>19,AA11<51),AND(AC11>1,AC11<6,AA11>0,AA11<20)),"Simples",IF(OR(AND(OR(AC11=1,AC11=0),AA11>50),AND(AC11>1,AC11<6,AA11>19,AA11<51),AND(AC11>5,AA11>0,AA11<20)),"Médio",IF(OR(AND(AC11>1,AC11<6,AA11>50),AND(AC11>5,AA11>19,AA11<51),AND(AC11>5,AA11>50)),"Complexo",""))), IF(Z11="AIE",IF(OR(AND(OR(AC11=1, AC11=0),AA11>0,AA11<20),AND(OR(AC11=1, AC11=0),AA11>19,AA11<51),AND(AC11>1,AC11<6,AA11>0,AA11<20)),"Simples",IF(OR(AND(OR(AC11=1, AC11=0),AA11>50),AND(AC11>1,AC11<6,AA11>19,AA11<51),AND(AC11>5,AA11>0,AA11<20)),"Médio",IF(OR(AND(AC11>1,AC11<6,AA11>50),AND(AC11>5,AA11>19,AA11<51),AND(AC11>5,AA11>50)),"Complexo",""))),"")) | AG11: =IF(AE11="",AF11,IF(AF11="",AE11,"")) | AH11: =IF(AND(OR(Z11="EE",Z11="CE"),AG11="Simples"),3, IF(AND(OR(Z11="EE",Z11="CE"),AG11="Médio"),4, IF(AND(OR(Z11="EE",Z11="CE"),AG11="Complexo"),6, IF(AND(Z11="SE",AG11="Simples"),4, IF(AND(Z11="SE",AG11="Médio"),5, IF(AND(Z11="SE",AG11="Complexo"),7,0)))))) -> 0 | AI11: =IF(AND(Z11="ALI",AF11="Simples"),7, IF(AND(Z11="ALI",AF11="Médio"),10, IF(AND(Z11="ALI",AF11="Complexo"),15, IF(AND(Z11="AIE",AF11="Simples"),5, IF(AND(Z11="AIE",AF11="Médio"),7, IF(AND(Z11="AIE",AF11="Complexo"),10,0)))))) -> 0 | AJ11: =IF(W11="OK",S11,( IF(X11<>"Manutenção em interface",IF(X11<>"Desenv., Manutenção e Publicação de Páginas Estáticas",(AH11+AI11)*Y11,Y11),Y11))) -> 0 | AP11: =IF(AJ11=0,"",IF(AJ11=S11,"OK","Divergente"))
B12: Guia de Métricas da STI - Aplicação/Desenvolvimento | C12: =IF(B12<>"",VLOOKUP(B12,'Tipo Projeto'!$A$3:$B$44,2,0),0) -> 1 | D12: Usuário | E12: HU-020_Cadastrar_Admin_Regionais.docx | F12: Consultar Usuário (implícito) | G12: EE | I12: 11 | J12: Login Nome CPF Telefone Celular Email Cargo Perfil UF Atuação Entidade Ação | K12: 1 | L12: Usuário | M12: =IF(G12="EE",IF(OR(AND(OR(K12=1,K12=0),I12>0,I12<5),AND(OR(K12=1,K12=0),I12>4,I12<16),AND(K12=2,I12>0,I12<5)),"Simples",IF(OR(AND(OR(K12=1,K12=0),I12>15),AND(K12=2,I12>4,I12<16),AND(K12>2,I12>0,I12<5)),"Médio",IF(OR(AND(K12=2,I12>15),AND(K12>2,I12>4,I12<16),AND(K12>2,I12>15)),"Complexo",""))), IF(OR(G12="CE",G12="SE"),IF(OR(AND(OR(K12=1,K12=0),I12>0,I12<6),AND(OR(K12=1,K12=0),I12>5,I12<20),AND(K12>1,K12<4,I12>0,I12<6)),"Simples",IF(OR(AND(OR(K12=1,K12=0),I12>19),AND(K12>1,K12<4,I12>5,I12<20),AND(K12>3,I12>0,I12<6)),"Médio",IF(OR(AND(K12>1,K12<4,I12>19),AND(K12>3,I12>5,I12<20),AND(K12>3,I12>19)),"Complexo",""))),"")) -> Simples | N12: =IF(G12="ALI",IF(OR(AND(OR(K12=1,K12=0),I12>0,I12<20),AND(OR(K12=1,K12=0),I12>19,I12<51),AND(K12>1,K12<6,I12>0,I12<20)),"Simples",IF(OR(AND(OR(K12=1,K12=0),I12>50),AND(K12>1,K12<6,I12>19,I12<51),AND(K12>5,I12>0,I12<20)),"Médio",IF(OR(AND(K12>1,K12<6,I12>50),AND(K12>5,I12>19,I12<51),AND(K12>5,I12>50)),"Complexo",""))), IF(G12="AIE",IF(OR(AND(OR(K12=1, K12=0),I12>0,I12<20),AND(OR(K12=1, K12=0),I12>19,I12<51),AND(K12>1,K12<6,I12>0,I12<20)),"Simples",IF(OR(AND(OR(K12=1, K12=0),I12>50),AND(K12>1,K12<6,I12>19,I12<51),AND(K12>5,I12>0,I12<20)),"Médio",IF(OR(AND(K12>1,K12<6,I12>50),AND(K12>5,I12>19,I12<51),AND(K12>5,I12>50)),"Complexo",""))),"")) | O12: =IF(M12="",N12,IF(N12="",M12,"")) -> Simples | P12: =IF(AND(OR(G12="EE",G12="CE"),O12="Simples"),3, IF(AND(OR(G12="EE",G12="CE"),O12="Médio"),4, IF(AND(OR(G12="EE",G12="CE"),O12="Complexo"),6, IF(AND(G12="SE",O12="Simples"),4, IF(AND(G12="SE",O12="Médio"),5, IF(AND(G12="SE",O12="Complexo"),7,0)))))) -> 3 | Q12: =IF(AND(G12="ALI",N12="Simples"),7, IF(AND(G12="ALI",N12="Médio"),10, IF(AND(G12="ALI",N12="Complexo"),15, IF(AND(G12="AIE",N12="Simples"),5, IF(AND(G12="AIE",N12="Médio"),7, IF(AND(G12="AIE",N12="Complexo"),10,0)))))) -> 0 | R12: =IF(G12="INM",C12*H12,IF(AND(OR(G12="EE",G12="CE"),O12="Simples"),3, IF(AND(OR(G12="EE",G12="CE"),O12="Médio"),4, IF(AND(OR(G12="EE",G12="CE"),O12="Complexo"),6, IF(AND(G12="SE",O12="Simples"),4, IF(AND(G12="SE",O12="Médio"),5, IF(AND(G12="SE",O12="Complexo"),7, IF(AND(G12="ALI",O12="Médio"),10, IF(AND(G12="ALI",O12="Simples"),7, IF(AND(G12="ALI",O12="Complexo"),15, IF(AND(G12="AIE",O12="Simples"),5, IF(AND(G12="AIE",O12="Médio"),7, IF(AND(G12="AIE",O12="Complexo"),10,0)) ))))))))))) -> 3 | S12: =IF(G12="INM",C12*H12,IF(B12<>"Manutenção em interface",IF(B12<>"Desenv., Manutenção e Publicação de Páginas Estáticas",(P12+Q12)*C12,C12),C12)) -> 3 | T12: 20 | Y12: =IF(X12<>"",VLOOKUP(X12,'Tipo Projeto'!$A$3:$B$44,2,0),0) -> 0 | AE12: =IF(Z12="EE",IF(OR(AND(OR(AC12=1,AC12=0),AA12>0,AA12<5),AND(OR(AC12=1,AC12=0),AA12>4,AA12<16),AND(AC12=2,AA12>0,AA12<5)),"Simples",IF(OR(AND(OR(AC12=1,AC12=0),AA12>15),AND(AC12=2,AA12>4,AA12<16),AND(AC12>2,AA12>0,AA12<5)),"Médio",IF(OR(AND(AC12=2,AA12>15),AND(AC12>2,AA12>4,AA12<16),AND(AC12>2,AA12>15)),"Complexo",""))), IF(OR(Z12="CE",Z12="SE"),IF(OR(AND(OR(AC12=1,AC12=0),AA12>0,AA12<6),AND(OR(AC12=1,AC12=0),AA12>5,AA12<20),AND(AC12>1,AC12<4,AA12>0,AA12<6)),"Simples",IF(OR(AND(OR(AC12=1,AC12=0),AA12>19),AND(AC12>1,AC12<4,AA12>5,AA12<20),AND(AC12>3,AA12>0,AA12<6)),"Médio",IF(OR(AND(AC12>1,AC12<4,AA12>19),AND(AC12>3,AA12>5,AA12<20),AND(AC12>3,AA12>19)),"Complexo",""))),"")) | AF12: =IF(Z12="ALI",IF(OR(AND(OR(AC12=1,AC12=0),AA12>0,AA12<20),AND(OR(AC12=1,AC12=0),AA12>19,AA12<51),AND(AC12>1,AC12<6,AA12>0,AA12<20)),"Simples",IF(OR(AND(OR(AC12=1,AC12=0),AA12>50),AND(AC12>1,AC12<6,AA12>19,AA12<51),AND(AC12>5,AA12>0,AA12<20)),"Médio",IF(OR(AND(AC12>1,AC12<6,AA12>50),AND(AC12>5,AA12>19,AA12<51),AND(AC12>5,AA12>50)),"Complexo",""))), IF(Z12="AIE",IF(OR(AND(OR(AC12=1, AC12=0),AA12>0,AA12<20),AND(OR(AC12=1, AC12=0),AA12>19,AA12<51),AND(AC12>1,AC12<6,AA12>0,AA12<20)),"Simples",IF(OR(AND(OR(AC12=1, AC12=0),AA12>50),AND(AC12>1,AC12<6,AA12>19,AA12<51),AND(AC12>5,AA12>0,AA12<20)),"Médio",IF(OR(AND(AC12>1,AC12<6,AA12>50),AND(AC12>5,AA12>19,AA12<51),AND(AC12>5,AA12>50)),"Complexo",""))),"")) | AG12: =IF(AE12="",AF12,IF(AF12="",AE12,"")) | AH12: =IF(AND(OR(Z12="EE",Z12="CE"),AG12="Simples"),3, IF(AND(OR(Z12="EE",Z12="CE"),AG12="Médio"),4, IF(AND(OR(Z12="EE",Z12="CE"),AG12="Complexo"),6, IF(AND(Z12="SE",AG12="Simples"),4, IF(AND(Z12="SE",AG12="Médio"),5, IF(AND(Z12="SE",AG12="Complexo"),7,0)))))) -> 0 | AI12: =IF(AND(Z12="ALI",AF12="Simples"),7, IF(AND(Z12="ALI",AF12="Médio"),10, IF(AND(Z12="ALI",AF12="Complexo"),15, IF(AND(Z12="AIE",AF12="Simples"),5, IF(AND(Z12="AIE",AF12="Médio"),7, IF(AND(Z12="AIE",AF12="Complexo"),10,0)))))) -> 0 | AJ12: =IF(W12="OK",S12,( IF(X12<>"Manutenção em interface",IF(X12<>"Desenv., Manutenção e Publicação de Páginas Estáticas",(AH12+AI12)*Y12,Y12),Y12))) -> 0 | AP12: =IF(AJ12=0,"",IF(AJ12=S12,"OK","Divergente"))
B13: Guia de Métricas da STI - Aplicação/Desenvolvimento | C13: =IF(B13<>"",VLOOKUP(B13,'Tipo Projeto'!$A$3:$B$44,2,0),0) -> 1 | D13: Usuário | E13: HU-020_Cadastrar_Admin_Regionais.docx | F13: Editar Usuário | G13: EE | I13: 11 | J13: Nome CPF Telefone Celular Email Cargo Perfil UF Atuação Entidade Ação Mensagem | K13: 1 | L13: Usuário | M13: =IF(G13="EE",IF(OR(AND(OR(K13=1,K13=0),I13>0,I13<5),AND(OR(K13=1,K13=0),I13>4,I13<16),AND(K13=2,I13>0,I13<5)),"Simples",IF(OR(AND(OR(K13=1,K13=0),I13>15),AND(K13=2,I13>4,I13<16),AND(K13>2,I13>0,I13<5)),"Médio",IF(OR(AND(K13=2,I13>15),AND(K13>2,I13>4,I13<16),AND(K13>2,I13>15)),"Complexo",""))), IF(OR(G13="CE",G13="SE"),IF(OR(AND(OR(K13=1,K13=0),I13>0,I13<6),AND(OR(K13=1,K13=0),I13>5,I13<20),AND(K13>1,K13<4,I13>0,I13<6)),"Simples",IF(OR(AND(OR(K13=1,K13=0),I13>19),AND(K13>1,K13<4,I13>5,I13<20),AND(K13>3,I13>0,I13<6)),"Médio",IF(OR(AND(K13>1,K13<4,I13>19),AND(K13>3,I13>5,I13<20),AND(K13>3,I13>19)),"Complexo",""))),"")) -> Simples | N13: =IF(G13="ALI",IF(OR(AND(OR(K13=1,K13=0),I13>0,I13<20),AND(OR(K13=1,K13=0),I13>19,I13<51),AND(K13>1,K13<6,I13>0,I13<20)),"Simples",IF(OR(AND(OR(K13=1,K13=0),I13>50),AND(K13>1,K13<6,I13>19,I13<51),AND(K13>5,I13>0,I13<20)),"Médio",IF(OR(AND(K13>1,K13<6,I13>50),AND(K13>5,I13>19,I13<51),AND(K13>5,I13>50)),"Complexo",""))), IF(G13="AIE",IF(OR(AND(OR(K13=1, K13=0),I13>0,I13<20),AND(OR(K13=1, K13=0),I13>19,I13<51),AND(K13>1,K13<6,I13>0,I13<20)),"Simples",IF(OR(AND(OR(K13=1, K13=0),I13>50),AND(K13>1,K13<6,I13>19,I13<51),AND(K13>5,I13>0,I13<20)),"Médio",IF(OR(AND(K13>1,K13<6,I13>50),AND(K13>5,I13>19,I13<51),AND(K13>5,I13>50)),"Complexo",""))),"")) | O13: =IF(M13="",N13,IF(N13="",M13,"")) -> Simples | P13: =IF(AND(OR(G13="EE",G13="CE"),O13="Simples"),3, IF(AND(OR(G13="EE",G13="CE"),O13="Médio"),4, IF(AND(OR(G13="EE",G13="CE"),O13="Complexo"),6, IF(AND(G13="SE",O13="Simples"),4, IF(AND(G13="SE",O13="Médio"),5, IF(AND(G13="SE",O13="Complexo"),7,0)))))) -> 3 | Q13: =IF(AND(G13="ALI",N13="Simples"),7, IF(AND(G13="ALI",N13="Médio"),10, IF(AND(G13="ALI",N13="Complexo"),15, IF(AND(G13="AIE",N13="Simples"),5, IF(AND(G13="AIE",N13="Médio"),7, IF(AND(G13="AIE",N13="Complexo"),10,0)))))) -> 0 | R13: =IF(G13="INM",C13*H13,IF(AND(OR(G13="EE",G13="CE"),O13="Simples"),3, IF(AND(OR(G13="EE",G13="CE"),O13="Médio"),4, IF(AND(OR(G13="EE",G13="CE"),O13="Complexo"),6, IF(AND(G13="SE",O13="Simples"),4, IF(AND(G13="SE",O13="Médio"),5, IF(AND(G13="SE",O13="Complexo"),7, IF(AND(G13="ALI",O13="Médio"),10, IF(AND(G13="ALI",O13="Simples"),7, IF(AND(G13="ALI",O13="Complexo"),15, IF(AND(G13="AIE",O13="Simples"),5, IF(AND(G13="AIE",O13="Médio"),7, IF(AND(G13="AIE",O13="Complexo"),10,0)) ))))))))))) -> 3 | S13: =IF(G13="INM",C13*H13,IF(B13<>"Manutenção em interface",IF(B13<>"Desenv., Manutenção e Publicação de Páginas Estáticas",(P13+Q13)*C13,C13),C13)) -> 3 | T13: 20 | Y13: =IF(X13<>"",VLOOKUP(X13,'Tipo Projeto'!$A$3:$B$44,2,0),0) -> 0 | AE13: =IF(Z13="EE",IF(OR(AND(OR(AC13=1,AC13=0),AA13>0,AA13<5),AND(OR(AC13=1,AC13=0),AA13>4,AA13<16),AND(AC13=2,AA13>0,AA13<5)),"Simples",IF(OR(AND(OR(AC13=1,AC13=0),AA13>15),AND(AC13=2,AA13>4,AA13<16),AND(AC13>2,AA13>0,AA13<5)),"Médio",IF(OR(AND(AC13=2,AA13>15),AND(AC13>2,AA13>4,AA13<16),AND(AC13>2,AA13>15)),"Complexo",""))), IF(OR(Z13="CE",Z13="SE"),IF(OR(AND(OR(AC13=1,AC13=0),AA13>0,AA13<6),AND(OR(AC13=1,AC13=0),AA13>5,AA13<20),AND(AC13>1,AC13<4,AA13>0,AA13<6)),"Simples",IF(OR(AND(OR(AC13=1,AC13=0),AA13>19),AND(AC13>1,AC13<4,AA13>5,AA13<20),AND(AC13>3,AA13>0,AA13<6)),"Médio",IF(OR(AND(AC13>1,AC13<4,AA13>19),AND(AC13>3,AA13>5,AA13<20),AND(AC13>3,AA13>19)),"Complexo",""))),"")) | AF13: =IF(Z13="ALI",IF(OR(AND(OR(AC13=1,AC13=0),AA13>0,AA13<20),AND(OR(AC13=1,AC13=0),AA13>19,AA13<51),AND(AC13>1,AC13<6,AA13>0,AA13<20)),"Simples",IF(OR(AND(OR(AC13=1,AC13=0),AA13>50),AND(AC13>1,AC13<6,AA13>19,AA13<51),AND(AC13>5,AA13>0,AA13<20)),"Médio",IF(OR(AND(AC13>1,AC13<6,AA13>50),AND(AC13>5,AA13>19,AA13<51),AND(AC13>5,AA13>50)),"Complexo",""))), IF(Z13="AIE",IF(OR(AND(OR(AC13=1, AC13=0),AA13>0,AA13<20),AND(OR(AC13=1, AC13=0),AA13>19,AA13<51),AND(AC13>1,AC13<6,AA13>0,AA13<20)),"Simples",IF(OR(AND(OR(AC13=1, AC13=0),AA13>50),AND(AC13>1,AC13<6,AA13>19,AA13<51),AND(AC13>5,AA13>0,AA13<20)),"Médio",IF(OR(AND(AC13>1,AC13<6,AA13>50),AND(AC13>5,AA13>19,AA13<51),AND(AC13>5,AA13>50)),"Complexo",""))),"")) | AG13: =IF(AE13="",AF13,IF(AF13="",AE13,"")) | AH13: =IF(AND(OR(Z13="EE",Z13="CE"),AG13="Simples"),3, IF(AND(OR(Z13="EE",Z13="CE"),AG13="Médio"),4, IF(AND(OR(Z13="EE",Z13="CE"),AG13="Complexo"),6, IF(AND(Z13="SE",AG13="Simples"),4, IF(AND(Z13="SE",AG13="Médio"),5, IF(AND(Z13="SE",AG13="Complexo"),7,0)))))) -> 0 | AI13: =IF(AND(Z13="ALI",AF13="Simples"),7, IF(AND(Z13="ALI",AF13="Médio"),10, IF(AND(Z13="ALI",AF13="Complexo"),15, IF(AND(Z13="AIE",AF13="Simples"),5, IF(AND(Z13="AIE",AF13="Médio"),7, IF(AND(Z13="AIE",AF13="Complexo"),10,0)))))) -> 0 | AJ13: =IF(W13="OK",S13,( IF(X13<>"Manutenção em interface",IF(X13<>"Desenv., Manutenção e Publicação de Páginas Estáticas",(AH13+AI13)*Y13,Y13),Y13))) -> 0 | AP13: =IF(AJ13=0,"",IF(AJ13=S13,"OK","Divergente"))
C14: =IF(B14<>"",VLOOKUP(B14,'Tipo Projeto'!$A$3:$B$44,2,0),0) -> 0 | M14: =IF(G14="EE",IF(OR(AND(OR(K14=1,K14=0),I14>0,I14<5),AND(OR(K14=1,K14=0),I14>4,I14<16),AND(K14=2,I14>0,I14<5)),"Simples",IF(OR(AND(OR(K14=1,K14=0),I14>15),AND(K14=2,I14>4,I14<16),AND(K14>2,I14>0,I14<5)),"Médio",IF(OR(AND(K14=2,I14>15),AND(K14>2,I14>4,I14<16),AND(K14>2,I14>15)),"Complexo",""))), IF(OR(G14="CE",G14="SE"),IF(OR(AND(OR(K14=1,K14=0),I14>0,I14<6),AND(OR(K14=1,K14=0),I14>5,I14<20),AND(K14>1,K14<4,I14>0,I14<6)),"Simples",IF(OR(AND(OR(K14=1,K14=0),I14>19),AND(K14>1,K14<4,I14>5,I14<20),AND(K14>3,I14>0,I14<6)),"Médio",IF(OR(AND(K14>1,K14<4,I14>19),AND(K14>3,I14>5,I14<20),AND(K14>3,I14>19)),"Complexo",""))),"")) | N14: =IF(G14="ALI",IF(OR(AND(OR(K14=1,K14=0),I14>0,I14<20),AND(OR(K14=1,K14=0),I14>19,I14<51),AND(K14>1,K14<6,I14>0,I14<20)),"Simples",IF(OR(AND(OR(K14=1,K14=0),I14>50),AND(K14>1,K14<6,I14>19,I14<51),AND(K14>5,I14>0,I14<20)),"Médio",IF(OR(AND(K14>1,K14<6,I14>50),AND(K14>5,I14>19,I14<51),AND(K14>5,I14>50)),"Complexo",""))), IF(G14="AIE",IF(OR(AND(OR(K14=1, K14=0),I14>0,I14<20),AND(OR(K14=1, K14=0),I14>19,I14<51),AND(K14>1,K14<6,I14>0,I14<20)),"Simples",IF(OR(AND(OR(K14=1, K14=0),I14>50),AND(K14>1,K14<6,I14>19,I14<51),AND(K14>5,I14>0,I14<20)),"Médio",IF(OR(AND(K14>1,K14<6,I14>50),AND(K14>5,I14>19,I14<51),AND(K14>5,I14>50)),"Complexo",""))),"")) | O14: =IF(M14="",N14,IF(N14="",M14,"")) | P14: =IF(AND(OR(G14="EE",G14="CE"),O14="Simples"),3, IF(AND(OR(G14="EE",G14="CE"),O14="Médio"),4, IF(AND(OR(G14="EE",G14="CE"),O14="Complexo"),6, IF(AND(G14="SE",O14="Simples"),4, IF(AND(G14="SE",O14="Médio"),5, IF(AND(G14="SE",O14="Complexo"),7,0)))))) -> 0 | Q14: =IF(AND(G14="ALI",N14="Simples"),7, IF(AND(G14="ALI",N14="Médio"),10, IF(AND(G14="ALI",N14="Complexo"),15, IF(AND(G14="AIE",N14="Simples"),5, IF(AND(G14="AIE",N14="Médio"),7, IF(AND(G14="AIE",N14="Complexo"),10,0)))))) -> 0 | R14: =IF(G14="INM",C14*H14,IF(AND(OR(G14="EE",G14="CE"),O14="Simples"),3, IF(AND(OR(G14="EE",G14="CE"),O14="Médio"),4, IF(AND(OR(G14="EE",G14="CE"),O14="Complexo"),6, IF(AND(G14="SE",O14="Simples"),4, IF(AND(G14="SE",O14="Médio"),5, IF(AND(G14="SE",O14="Complexo"),7, IF(AND(G14="ALI",O14="Médio"),10, IF(AND(G14="ALI",O14="Simples"),7, IF(AND(G14="ALI",O14="Complexo"),15, IF(AND(G14="AIE",O14="Simples"),5, IF(AND(G14="AIE",O14="Médio"),7, IF(AND(G14="AIE",O14="Complexo"),10,0)) ))))))))))) -> 0 | S14: =IF(G14="INM",C14*H14,IF(B14<>"Manutenção em interface",IF(B14<>"Desenv., Manutenção e Publicação de Páginas Estáticas",(P14+Q14)*C14,C14),C14)) -> 0 | Y14: =IF(X14<>"",VLOOKUP(X14,'Tipo Projeto'!$A$3:$B$44,2,0),0) -> 0 | AE14: =IF(Z14="EE",IF(OR(AND(OR(AC14=1,AC14=0),AA14>0,AA14<5),AND(OR(AC14=1,AC14=0),AA14>4,AA14<16),AND(AC14=2,AA14>0,AA14<5)),"Simples",IF(OR(AND(OR(AC14=1,AC14=0),AA14>15),AND(AC14=2,AA14>4,AA14<16),AND(AC14>2,AA14>0,AA14<5)),"Médio",IF(OR(AND(AC14=2,AA14>15),AND(AC14>2,AA14>4,AA14<16),AND(AC14>2,AA14>15)),"Complexo",""))), IF(OR(Z14="CE",Z14="SE"),IF(OR(AND(OR(AC14=1,AC14=0),AA14>0,AA14<6),AND(OR(AC14=1,AC14=0),AA14>5,AA14<20),AND(AC14>1,AC14<4,AA14>0,AA14<6)),"Simples",IF(OR(AND(OR(AC14=1,AC14=0),AA14>19),AND(AC14>1,AC14<4,AA14>5,AA14<20),AND(AC14>3,AA14>0,AA14<6)),"Médio",IF(OR(AND(AC14>1,AC14<4,AA14>19),AND(AC14>3,AA14>5,AA14<20),AND(AC14>3,AA14>19)),"Complexo",""))),"")) | AF14: =IF(Z14="ALI",IF(OR(AND(OR(AC14=1,AC14=0),AA14>0,AA14<20),AND(OR(AC14=1,AC14=0),AA14>19,AA14<51),AND(AC14>1,AC14<6,AA14>0,AA14<20)),"Simples",IF(OR(AND(OR(AC14=1,AC14=0),AA14>50),AND(AC14>1,AC14<6,AA14>19,AA14<51),AND(AC14>5,AA14>0,AA14<20)),"Médio",IF(OR(AND(AC14>1,AC14<6,AA14>50),AND(AC14>5,AA14>19,AA14<51),AND(AC14>5,AA14>50)),"Complexo",""))), IF(Z14="AIE",IF(OR(AND(OR(AC14=1, AC14=0),AA14>0,AA14<20),AND(OR(AC14=1, AC14=0),AA14>19,AA14<51),AND(AC14>1,AC14<6,AA14>0,AA14<20)),"Simples",IF(OR(AND(OR(AC14=1, AC14=0),AA14>50),AND(AC14>1,AC14<6,AA14>19,AA14<51),AND(AC14>5,AA14>0,AA14<20)),"Médio",IF(OR(AND(AC14>1,AC14<6,AA14>50),AND(AC14>5,AA14>19,AA14<51),AND(AC14>5,AA14>50)),"Complexo",""))),"")) | AG14: =IF(AE14="",AF14,IF(AF14="",AE14,"")) | AH14: =IF(AND(OR(Z14="EE",Z14="CE"),AG14="Simples"),3, IF(AND(OR(Z14="EE",Z14="CE"),AG14="Médio"),4, IF(AND(OR(Z14="EE",Z14="CE"),AG14="Complexo"),6, IF(AND(Z14="SE",AG14="Simples"),4, IF(AND(Z14="SE",AG14="Médio"),5, IF(AND(Z14="SE",AG14="Complexo"),7,0)))))) -> 0 | AI14: =IF(AND(Z14="ALI",AF14="Simples"),7, IF(AND(Z14="ALI",AF14="Médio"),10, IF(AND(Z14="ALI",AF14="Complexo"),15, IF(AND(Z14="AIE",AF14="Simples"),5, IF(AND(Z14="AIE",AF14="Médio"),7, IF(AND(Z14="AIE",AF14="Complexo"),10,0)))))) -> 0 | AJ14: =IF(W14="OK",S14,( IF(X14<>"Manutenção em interface",IF(X14<>"Desenv., Manutenção e Publicação de Páginas Estáticas",(AH14+AI14)*Y14,Y14),Y14))) -> 0 | AP14: =IF(AJ14=0,"",IF(AJ14=S14,"OK","Divergente"))
B15: Guia de Métricas da STI - Aplicação/Desenvolvimento | C15: =IF(B15<>"",VLOOKUP(B15,'Tipo Projeto'!$A$3:$B$44,2,0),0) -> 1 | D15: Categoria | F15: Pesquisar Categorias | G15: SE | I15: 6 | J15: Nome Descrição Qtd Vinculos Status Ação Mensagem | K15: 2 | L15: Categoria Premiação | M15: =IF(G15="EE",IF(OR(AND(OR(K15=1,K15=0),I15>0,I15<5),AND(OR(K15=1,K15=0),I15>4,I15<16),AND(K15=2,I15>0,I15<5)),"Simples",IF(OR(AND(OR(K15=1,K15=0),I15>15),AND(K15=2,I15>4,I15<16),AND(K15>2,I15>0,I15<5)),"Médio",IF(OR(AND(K15=2,I15>15),AND(K15>2,I15>4,I15<16),AND(K15>2,I15>15)),"Complexo",""))), IF(OR(G15="CE",G15="SE"),IF(OR(AND(OR(K15=1,K15=0),I15>0,I15<6),AND(OR(K15=1,K15=0),I15>5,I15<20),AND(K15>1,K15<4,I15>0,I15<6)),"Simples",IF(OR(AND(OR(K15=1,K15=0),I15>19),AND(K15>1,K15<4,I15>5,I15<20),AND(K15>3,I15>0,I15<6)),"Médio",IF(OR(AND(K15>1,K15<4,I15>19),AND(K15>3,I15>5,I15<20),AND(K15>3,I15>19)),"Complexo",""))),"")) -> Médio | N15: =IF(G15="ALI",IF(OR(AND(OR(K15=1,K15=0),I15>0,I15<20),AND(OR(K15=1,K15=0),I15>19,I15<51),AND(K15>1,K15<6,I15>0,I15<20)),"Simples",IF(OR(AND(OR(K15=1,K15=0),I15>50),AND(K15>1,K15<6,I15>19,I15<51),AND(K15>5,I15>0,I15<20)),"Médio",IF(OR(AND(K15>1,K15<6,I15>50),AND(K15>5,I15>19,I15<51),AND(K15>5,I15>50)),"Complexo",""))), IF(G15="AIE",IF(OR(AND(OR(K15=1, K15=0),I15>0,I15<20),AND(OR(K15=1, K15=0),I15>19,I15<51),AND(K15>1,K15<6,I15>0,I15<20)),"Simples",IF(OR(AND(OR(K15=1, K15=0),I15>50),AND(K15>1,K15<6,I15>19,I15<51),AND(K15>5,I15>0,I15<20)),"Médio",IF(OR(AND(K15>1,K15<6,I15>50),AND(K15>5,I15>19,I15<51),AND(K15>5,I15>50)),"Complexo",""))),"")) | O15: =IF(M15="",N15,IF(N15="",M15,"")) -> Médio | P15: =IF(AND(OR(G15="EE",G15="CE"),O15="Simples"),3, IF(AND(OR(G15="EE",G15="CE"),O15="Médio"),4, IF(AND(OR(G15="EE",G15="CE"),O15="Complexo"),6, IF(AND(G15="SE",O15="Simples"),4, IF(AND(G15="SE",O15="Médio"),5, IF(AND(G15="SE",O15="Complexo"),7,0)))))) -> 5 | Q15: =IF(AND(G15="ALI",N15="Simples"),7, IF(AND(G15="ALI",N15="Médio"),10, IF(AND(G15="ALI",N15="Complexo"),15, IF(AND(G15="AIE",N15="Simples"),5, IF(AND(G15="AIE",N15="Médio"),7, IF(AND(G15="AIE",N15="Complexo"),10,0)))))) -> 0 | R15: =IF(G15="INM",C15*H15,IF(AND(OR(G15="EE",G15="CE"),O15="Simples"),3, IF(AND(OR(G15="EE",G15="CE"),O15="Médio"),4, IF(AND(OR(G15="EE",G15="CE"),O15="Complexo"),6, IF(AND(G15="SE",O15="Simples"),4, IF(AND(G15="SE",O15="Médio"),5, IF(AND(G15="SE",O15="Complexo"),7, IF(AND(G15="ALI",O15="Médio"),10, IF(AND(G15="ALI",O15="Simples"),7, IF(AND(G15="ALI",O15="Complexo"),15, IF(AND(G15="AIE",O15="Simples"),5, IF(AND(G15="AIE",O15="Médio"),7, IF(AND(G15="AIE",O15="Complexo"),10,0)) ))))))))))) -> 5 | S15: =IF(G15="INM",C15*H15,IF(B15<>"Manutenção em interface",IF(B15<>"Desenv., Manutenção e Publicação de Páginas Estáticas",(P15+Q15)*C15,C15),C15)) -> 5 | T15: PDTIC25093-16 | Y15: =IF(X15<>"",VLOOKUP(X15,'Tipo Projeto'!$A$3:$B$44,2,0),0) -> 0 | AE15: =IF(Z15="EE",IF(OR(AND(OR(AC15=1,AC15=0),AA15>0,AA15<5),AND(OR(AC15=1,AC15=0),AA15>4,AA15<16),AND(AC15=2,AA15>0,AA15<5)),"Simples",IF(OR(AND(OR(AC15=1,AC15=0),AA15>15),AND(AC15=2,AA15>4,AA15<16),AND(AC15>2,AA15>0,AA15<5)),"Médio",IF(OR(AND(AC15=2,AA15>15),AND(AC15>2,AA15>4,AA15<16),AND(AC15>2,AA15>15)),"Complexo",""))), IF(OR(Z15="CE",Z15="SE"),IF(OR(AND(OR(AC15=1,AC15=0),AA15>0,AA15<6),AND(OR(AC15=1,AC15=0),AA15>5,AA15<20),AND(AC15>1,AC15<4,AA15>0,AA15<6)),"Simples",IF(OR(AND(OR(AC15=1,AC15=0),AA15>19),AND(AC15>1,AC15<4,AA15>5,AA15<20),AND(AC15>3,AA15>0,AA15<6)),"Médio",IF(OR(AND(AC15>1,AC15<4,AA15>19),AND(AC15>3,AA15>5,AA15<20),AND(AC15>3,AA15>19)),"Complexo",""))),"")) | AF15: =IF(Z15="ALI",IF(OR(AND(OR(AC15=1,AC15=0),AA15>0,AA15<20),AND(OR(AC15=1,AC15=0),AA15>19,AA15<51),AND(AC15>1,AC15<6,AA15>0,AA15<20)),"Simples",IF(OR(AND(OR(AC15=1,AC15=0),AA15>50),AND(AC15>1,AC15<6,AA15>19,AA15<51),AND(AC15>5,AA15>0,AA15<20)),"Médio",IF(OR(AND(AC15>1,AC15<6,AA15>50),AND(AC15>5,AA15>19,AA15<51),AND(AC15>5,AA15>50)),"Complexo",""))), IF(Z15="AIE",IF(OR(AND(OR(AC15=1, AC15=0),AA15>0,AA15<20),AND(OR(AC15=1, AC15=0),AA15>19,AA15<51),AND(AC15>1,AC15<6,AA15>0,AA15<20)),"Simples",IF(OR(AND(OR(AC15=1, AC15=0),AA15>50),AND(AC15>1,AC15<6,AA15>19,AA15<51),AND(AC15>5,AA15>0,AA15<20)),"Médio",IF(OR(AND(AC15>1,AC15<6,AA15>50),AND(AC15>5,AA15>19,AA15<51),AND(AC15>5,AA15>50)),"Complexo",""))),"")) | AG15: =IF(AE15="",AF15,IF(AF15="",AE15,"")) | AH15: =IF(AND(OR(Z15="EE",Z15="CE"),AG15="Simples"),3, IF(AND(OR(Z15="EE",Z15="CE"),AG15="Médio"),4, IF(AND(OR(Z15="EE",Z15="CE"),AG15="Complexo"),6, IF(AND(Z15="SE",AG15="Simples"),4, IF(AND(Z15="SE",AG15="Médio"),5, IF(AND(Z15="SE",AG15="Complexo"),7,0)))))) -> 0 | AI15: =IF(AND(Z15="ALI",AF15="Simples"),7, IF(AND(Z15="ALI",AF15="Médio"),10, IF(AND(Z15="ALI",AF15="Complexo"),15, IF(AND(Z15="AIE",AF15="Simples"),5, IF(AND(Z15="AIE",AF15="Médio"),7, IF(AND(Z15="AIE",AF15="Complexo"),10,0)))))) -> 0 | AJ15: =IF(W15="OK",S15,( IF(X15<>"Manutenção em interface",IF(X15<>"Desenv., Manutenção e Publicação de Páginas Estáticas",(AH15+AI15)*Y15,Y15),Y15))) -> 0 | AP15: =IF(AJ15=0,"",IF(AJ15=S15,"OK","Divergente"))
B16: Guia de Métricas da STI - Aplicação/Desenvolvimento | C16: =IF(B16<>"",VLOOKUP(B16,'Tipo Projeto'!$A$3:$B$44,2,0),0) -> 1 | D16: Categoria | F16: Incluir Categoria | G16: EE | I16: 4 | J16: Nome Descrição Ação Mensagem | K16: 1 | L16: Categoria Premiação | M16: =IF(G16="EE",IF(OR(AND(OR(K16=1,K16=0),I16>0,I16<5),AND(OR(K16=1,K16=0),I16>4,I16<16),AND(K16=2,I16>0,I16<5)),"Simples",IF(OR(AND(OR(K16=1,K16=0),I16>15),AND(K16=2,I16>4,I16<16),AND(K16>2,I16>0,I16<5)),"Médio",IF(OR(AND(K16=2,I16>15),AND(K16>2,I16>4,I16<16),AND(K16>2,I16>15)),"Complexo",""))), IF(OR(G16="CE",G16="SE"),IF(OR(AND(OR(K16=1,K16=0),I16>0,I16<6),AND(OR(K16=1,K16=0),I16>5,I16<20),AND(K16>1,K16<4,I16>0,I16<6)),"Simples",IF(OR(AND(OR(K16=1,K16=0),I16>19),AND(K16>1,K16<4,I16>5,I16<20),AND(K16>3,I16>0,I16<6)),"Médio",IF(OR(AND(K16>1,K16<4,I16>19),AND(K16>3,I16>5,I16<20),AND(K16>3,I16>19)),"Complexo",""))),"")) -> Simples | N16: =IF(G16="ALI",IF(OR(AND(OR(K16=1,K16=0),I16>0,I16<20),AND(OR(K16=1,K16=0),I16>19,I16<51),AND(K16>1,K16<6,I16>0,I16<20)),"Simples",IF(OR(AND(OR(K16=1,K16=0),I16>50),AND(K16>1,K16<6,I16>19,I16<51),AND(K16>5,I16>0,I16<20)),"Médio",IF(OR(AND(K16>1,K16<6,I16>50),AND(K16>5,I16>19,I16<51),AND(K16>5,I16>50)),"Complexo",""))), IF(G16="AIE",IF(OR(AND(OR(K16=1, K16=0),I16>0,I16<20),AND(OR(K16=1, K16=0),I16>19,I16<51),AND(K16>1,K16<6,I16>0,I16<20)),"Simples",IF(OR(AND(OR(K16=1, K16=0),I16>50),AND(K16>1,K16<6,I16>19,I16<51),AND(K16>5,I16>0,I16<20)),"Médio",IF(OR(AND(K16>1,K16<6,I16>50),AND(K16>5,I16>19,I16<51),AND(K16>5,I16>50)),"Complexo",""))),"")) | O16: =IF(M16="",N16,IF(N16="",M16,"")) -> Simples | P16: =IF(AND(OR(G16="EE",G16="CE"),O16="Simples"),3, IF(AND(OR(G16="EE",G16="CE"),O16="Médio"),4, IF(AND(OR(G16="EE",G16="CE"),O16="Complexo"),6, IF(AND(G16="SE",O16="Simples"),4, IF(AND(G16="SE",O16="Médio"),5, IF(AND(G16="SE",O16="Complexo"),7,0)))))) -> 3 | Q16: =IF(AND(G16="ALI",N16="Simples"),7, IF(AND(G16="ALI",N16="Médio"),10, IF(AND(G16="ALI",N16="Complexo"),15, IF(AND(G16="AIE",N16="Simples"),5, IF(AND(G16="AIE",N16="Médio"),7, IF(AND(G16="AIE",N16="Complexo"),10,0)))))) -> 0 | R16: =IF(G16="INM",C16*H16,IF(AND(OR(G16="EE",G16="CE"),O16="Simples"),3, IF(AND(OR(G16="EE",G16="CE"),O16="Médio"),4, IF(AND(OR(G16="EE",G16="CE"),O16="Complexo"),6, IF(AND(G16="SE",O16="Simples"),4, IF(AND(G16="SE",O16="Médio"),5, IF(AND(G16="SE",O16="Complexo"),7, IF(AND(G16="ALI",O16="Médio"),10, IF(AND(G16="ALI",O16="Simples"),7, IF(AND(G16="ALI",O16="Complexo"),15, IF(AND(G16="AIE",O16="Simples"),5, IF(AND(G16="AIE",O16="Médio"),7, IF(AND(G16="AIE",O16="Complexo"),10,0)) ))))))))))) -> 3 | S16: =IF(G16="INM",C16*H16,IF(B16<>"Manutenção em interface",IF(B16<>"Desenv., Manutenção e Publicação de Páginas Estáticas",(P16+Q16)*C16,C16),C16)) -> 3 | T16: PDTIC25093-16 | Y16: =IF(X16<>"",VLOOKUP(X16,'Tipo Projeto'!$A$3:$B$44,2,0),0) -> 0 | AE16: =IF(Z16="EE",IF(OR(AND(OR(AC16=1,AC16=0),AA16>0,AA16<5),AND(OR(AC16=1,AC16=0),AA16>4,AA16<16),AND(AC16=2,AA16>0,AA16<5)),"Simples",IF(OR(AND(OR(AC16=1,AC16=0),AA16>15),AND(AC16=2,AA16>4,AA16<16),AND(AC16>2,AA16>0,AA16<5)),"Médio",IF(OR(AND(AC16=2,AA16>15),AND(AC16>2,AA16>4,AA16<16),AND(AC16>2,AA16>15)),"Complexo",""))), IF(OR(Z16="CE",Z16="SE"),IF(OR(AND(OR(AC16=1,AC16=0),AA16>0,AA16<6),AND(OR(AC16=1,AC16=0),AA16>5,AA16<20),AND(AC16>1,AC16<4,AA16>0,AA16<6)),"Simples",IF(OR(AND(OR(AC16=1,AC16=0),AA16>19),AND(AC16>1,AC16<4,AA16>5,AA16<20),AND(AC16>3,AA16>0,AA16<6)),"Médio",IF(OR(AND(AC16>1,AC16<4,AA16>19),AND(AC16>3,AA16>5,AA16<20),AND(AC16>3,AA16>19)),"Complexo",""))),"")) | AF16: =IF(Z16="ALI",IF(OR(AND(OR(AC16=1,AC16=0),AA16>0,AA16<20),AND(OR(AC16=1,AC16=0),AA16>19,AA16<51),AND(AC16>1,AC16<6,AA16>0,AA16<20)),"Simples",IF(OR(AND(OR(AC16=1,AC16=0),AA16>50),AND(AC16>1,AC16<6,AA16>19,AA16<51),AND(AC16>5,AA16>0,AA16<20)),"Médio",IF(OR(AND(AC16>1,AC16<6,AA16>50),AND(AC16>5,AA16>19,AA16<51),AND(AC16>5,AA16>50)),"Complexo",""))), IF(Z16="AIE",IF(OR(AND(OR(AC16=1, AC16=0),AA16>0,AA16<20),AND(OR(AC16=1, AC16=0),AA16>19,AA16<51),AND(AC16>1,AC16<6,AA16>0,AA16<20)),"Simples",IF(OR(AND(OR(AC16=1, AC16=0),AA16>50),AND(AC16>1,AC16<6,AA16>19,AA16<51),AND(AC16>5,AA16>0,AA16<20)),"Médio",IF(OR(AND(AC16>1,AC16<6,AA16>50),AND(AC16>5,AA16>19,AA16<51),AND(AC16>5,AA16>50)),"Complexo",""))),"")) | AG16: =IF(AE16="",AF16,IF(AF16="",AE16,"")) | AH16: =IF(AND(OR(Z16="EE",Z16="CE"),AG16="Simples"),3, IF(AND(OR(Z16="EE",Z16="CE"),AG16="Médio"),4, IF(AND(OR(Z16="EE",Z16="CE"),AG16="Complexo"),6, IF(AND(Z16="SE",AG16="Simples"),4, IF(AND(Z16="SE",AG16="Médio"),5, IF(AND(Z16="SE",AG16="Complexo"),7,0)))))) -> 0 | AI16: =IF(AND(Z16="ALI",AF16="Simples"),7, IF(AND(Z16="ALI",AF16="Médio"),10, IF(AND(Z16="ALI",AF16="Complexo"),15, IF(AND(Z16="AIE",AF16="Simples"),5, IF(AND(Z16="AIE",AF16="Médio"),7, IF(AND(Z16="AIE",AF16="Complexo"),10,0)))))) -> 0 | AJ16: =IF(W16="OK",S16,( IF(X16<>"Manutenção em interface",IF(X16<>"Desenv., Manutenção e Publicação de Páginas Estáticas",(AH16+AI16)*Y16,Y16),Y16))) -> 0 | AP16: =IF(AJ16=0,"",IF(AJ16=S16,"OK","Divergente"))
B17: Guia de Métricas da STI - Aplicação/Desenvolvimento | C17: =IF(B17<>"",VLOOKUP(B17,'Tipo Projeto'!$A$3:$B$44,2,0),0) -> 1 | D17: Categoria | F17: Consultar Categoria (implícita) | G17: SE | I17: 6 | J17: Nome Descrição Premiação Id do Vinculo Situação Ação | K17: 2 | L17: Categoria Premiação | M17: =IF(G17="EE",IF(OR(AND(OR(K17=1,K17=0),I17>0,I17<5),AND(OR(K17=1,K17=0),I17>4,I17<16),AND(K17=2,I17>0,I17<5)),"Simples",IF(OR(AND(OR(K17=1,K17=0),I17>15),AND(K17=2,I17>4,I17<16),AND(K17>2,I17>0,I17<5)),"Médio",IF(OR(AND(K17=2,I17>15),AND(K17>2,I17>4,I17<16),AND(K17>2,I17>15)),"Complexo",""))), IF(OR(G17="CE",G17="SE"),IF(OR(AND(OR(K17=1,K17=0),I17>0,I17<6),AND(OR(K17=1,K17=0),I17>5,I17<20),AND(K17>1,K17<4,I17>0,I17<6)),"Simples",IF(OR(AND(OR(K17=1,K17=0),I17>19),AND(K17>1,K17<4,I17>5,I17<20),AND(K17>3,I17>0,I17<6)),"Médio",IF(OR(AND(K17>1,K17<4,I17>19),AND(K17>3,I17>5,I17<20),AND(K17>3,I17>19)),"Complexo",""))),"")) -> Médio | N17: =IF(G17="ALI",IF(OR(AND(OR(K17=1,K17=0),I17>0,I17<20),AND(OR(K17=1,K17=0),I17>19,I17<51),AND(K17>1,K17<6,I17>0,I17<20)),"Simples",IF(OR(AND(OR(K17=1,K17=0),I17>50),AND(K17>1,K17<6,I17>19,I17<51),AND(K17>5,I17>0,I17<20)),"Médio",IF(OR(AND(K17>1,K17<6,I17>50),AND(K17>5,I17>19,I17<51),AND(K17>5,I17>50)),"Complexo",""))), IF(G17="AIE",IF(OR(AND(OR(K17=1, K17=0),I17>0,I17<20),AND(OR(K17=1, K17=0),I17>19,I17<51),AND(K17>1,K17<6,I17>0,I17<20)),"Simples",IF(OR(AND(OR(K17=1, K17=0),I17>50),AND(K17>1,K17<6,I17>19,I17<51),AND(K17>5,I17>0,I17<20)),"Médio",IF(OR(AND(K17>1,K17<6,I17>50),AND(K17>5,I17>19,I17<51),AND(K17>5,I17>50)),"Complexo",""))),"")) | O17: =IF(M17="",N17,IF(N17="",M17,"")) -> Médio | P17: =IF(AND(OR(G17="EE",G17="CE"),O17="Simples"),3, IF(AND(OR(G17="EE",G17="CE"),O17="Médio"),4, IF(AND(OR(G17="EE",G17="CE"),O17="Complexo"),6, IF(AND(G17="SE",O17="Simples"),4, IF(AND(G17="SE",O17="Médio"),5, IF(AND(G17="SE",O17="Complexo"),7,0)))))) -> 5 | Q17: =IF(AND(G17="ALI",N17="Simples"),7, IF(AND(G17="ALI",N17="Médio"),10, IF(AND(G17="ALI",N17="Complexo"),15, IF(AND(G17="AIE",N17="Simples"),5, IF(AND(G17="AIE",N17="Médio"),7, IF(AND(G17="AIE",N17="Complexo"),10,0)))))) -> 0 | R17: =IF(G17="INM",C17*H17,IF(AND(OR(G17="EE",G17="CE"),O17="Simples"),3, IF(AND(OR(G17="EE",G17="CE"),O17="Médio"),4, IF(AND(OR(G17="EE",G17="CE"),O17="Complexo"),6, IF(AND(G17="SE",O17="Simples"),4, IF(AND(G17="SE",O17="Médio"),5, IF(AND(G17="SE",O17="Complexo"),7, IF(AND(G17="ALI",O17="Médio"),10, IF(AND(G17="ALI",O17="Simples"),7, IF(AND(G17="ALI",O17="Complexo"),15, IF(AND(G17="AIE",O17="Simples"),5, IF(AND(G17="AIE",O17="Médio"),7, IF(AND(G17="AIE",O17="Complexo"),10,0)) ))))))))))) -> 5 | S17: =IF(G17="INM",C17*H17,IF(B17<>"Manutenção em interface",IF(B17<>"Desenv., Manutenção e Publicação de Páginas Estáticas",(P17+Q17)*C17,C17),C17)) -> 5 | T17: PDTIC25093-16 | Y17: =IF(X17<>"",VLOOKUP(X17,'Tipo Projeto'!$A$3:$B$44,2,0),0) -> 0 | AE17: =IF(Z17="EE",IF(OR(AND(OR(AC17=1,AC17=0),AA17>0,AA17<5),AND(OR(AC17=1,AC17=0),AA17>4,AA17<16),AND(AC17=2,AA17>0,AA17<5)),"Simples",IF(OR(AND(OR(AC17=1,AC17=0),AA17>15),AND(AC17=2,AA17>4,AA17<16),AND(AC17>2,AA17>0,AA17<5)),"Médio",IF(OR(AND(AC17=2,AA17>15),AND(AC17>2,AA17>4,AA17<16),AND(AC17>2,AA17>15)),"Complexo",""))), IF(OR(Z17="CE",Z17="SE"),IF(OR(AND(OR(AC17=1,AC17=0),AA17>0,AA17<6),AND(OR(AC17=1,AC17=0),AA17>5,AA17<20),AND(AC17>1,AC17<4,AA17>0,AA17<6)),"Simples",IF(OR(AND(OR(AC17=1,AC17=0),AA17>19),AND(AC17>1,AC17<4,AA17>5,AA17<20),AND(AC17>3,AA17>0,AA17<6)),"Médio",IF(OR(AND(AC17>1,AC17<4,AA17>19),AND(AC17>3,AA17>5,AA17<20),AND(AC17>3,AA17>19)),"Complexo",""))),"")) | AF17: =IF(Z17="ALI",IF(OR(AND(OR(AC17=1,AC17=0),AA17>0,AA17<20),AND(OR(AC17=1,AC17=0),AA17>19,AA17<51),AND(AC17>1,AC17<6,AA17>0,AA17<20)),"Simples",IF(OR(AND(OR(AC17=1,AC17=0),AA17>50),AND(AC17>1,AC17<6,AA17>19,AA17<51),AND(AC17>5,AA17>0,AA17<20)),"Médio",IF(OR(AND(AC17>1,AC17<6,AA17>50),AND(AC17>5,AA17>19,AA17<51),AND(AC17>5,AA17>50)),"Complexo",""))), IF(Z17="AIE",IF(OR(AND(OR(AC17=1, AC17=0),AA17>0,AA17<20),AND(OR(AC17=1, AC17=0),AA17>19,AA17<51),AND(AC17>1,AC17<6,AA17>0,AA17<20)),"Simples",IF(OR(AND(OR(AC17=1, AC17=0),AA17>50),AND(AC17>1,AC17<6,AA17>19,AA17<51),AND(AC17>5,AA17>0,AA17<20)),"Médio",IF(OR(AND(AC17>1,AC17<6,AA17>50),AND(AC17>5,AA17>19,AA17<51),AND(AC17>5,AA17>50)),"Complexo",""))),"")) | AG17: =IF(AE17="",AF17,IF(AF17="",AE17,"")) | AH17: =IF(AND(OR(Z17="EE",Z17="CE"),AG17="Simples"),3, IF(AND(OR(Z17="EE",Z17="CE"),AG17="Médio"),4, IF(AND(OR(Z17="EE",Z17="CE"),AG17="Complexo"),6, IF(AND(Z17="SE",AG17="Simples"),4, IF(AND(Z17="SE",AG17="Médio"),5, IF(AND(Z17="SE",AG17="Complexo"),7,0)))))) -> 0 | AI17: =IF(AND(Z17="ALI",AF17="Simples"),7, IF(AND(Z17="ALI",AF17="Médio"),10, IF(AND(Z17="ALI",AF17="Complexo"),15, IF(AND(Z17="AIE",AF17="Simples"),5, IF(AND(Z17="AIE",AF17="Médio"),7, IF(AND(Z17="AIE",AF17="Complexo"),10,0)))))) -> 0 | AJ17: =IF(W17="OK",S17,( IF(X17<>"Manutenção em interface",IF(X17<>"Desenv., Manutenção e Publicação de Páginas Estáticas",(AH17+AI17)*Y17,Y17),Y17))) -> 0 | AP17: =IF(AJ17=0,"",IF(AJ17=S17,"OK","Divergente"))
B18: Guia de Métricas da STI - Aplicação/Desenvolvimento | C18: =IF(B18<>"",VLOOKUP(B18,'Tipo Projeto'!$A$3:$B$44,2,0),0) -> 1 | D18: Categoria | F18: Editar Categoria | G18: EE | I18: 4 | J18: Nome Descrição Ação Mensagem | K18: 1 | L18: Categoria Premiação | M18: =IF(G18="EE",IF(OR(AND(OR(K18=1,K18=0),I18>0,I18<5),AND(OR(K18=1,K18=0),I18>4,I18<16),AND(K18=2,I18>0,I18<5)),"Simples",IF(OR(AND(OR(K18=1,K18=0),I18>15),AND(K18=2,I18>4,I18<16),AND(K18>2,I18>0,I18<5)),"Médio",IF(OR(AND(K18=2,I18>15),AND(K18>2,I18>4,I18<16),AND(K18>2,I18>15)),"Complexo",""))), IF(OR(G18="CE",G18="SE"),IF(OR(AND(OR(K18=1,K18=0),I18>0,I18<6),AND(OR(K18=1,K18=0),I18>5,I18<20),AND(K18>1,K18<4,I18>0,I18<6)),"Simples",IF(OR(AND(OR(K18=1,K18=0),I18>19),AND(K18>1,K18<4,I18>5,I18<20),AND(K18>3,I18>0,I18<6)),"Médio",IF(OR(AND(K18>1,K18<4,I18>19),AND(K18>3,I18>5,I18<20),AND(K18>3,I18>19)),"Complexo",""))),"")) -> Simples | N18: =IF(G18="ALI",IF(OR(AND(OR(K18=1,K18=0),I18>0,I18<20),AND(OR(K18=1,K18=0),I18>19,I18<51),AND(K18>1,K18<6,I18>0,I18<20)),"Simples",IF(OR(AND(OR(K18=1,K18=0),I18>50),AND(K18>1,K18<6,I18>19,I18<51),AND(K18>5,I18>0,I18<20)),"Médio",IF(OR(AND(K18>1,K18<6,I18>50),AND(K18>5,I18>19,I18<51),AND(K18>5,I18>50)),"Complexo",""))), IF(G18="AIE",IF(OR(AND(OR(K18=1, K18=0),I18>0,I18<20),AND(OR(K18=1, K18=0),I18>19,I18<51),AND(K18>1,K18<6,I18>0,I18<20)),"Simples",IF(OR(AND(OR(K18=1, K18=0),I18>50),AND(K18>1,K18<6,I18>19,I18<51),AND(K18>5,I18>0,I18<20)),"Médio",IF(OR(AND(K18>1,K18<6,I18>50),AND(K18>5,I18>19,I18<51),AND(K18>5,I18>50)),"Complexo",""))),"")) | O18: =IF(M18="",N18,IF(N18="",M18,"")) -> Simples | P18: =IF(AND(OR(G18="EE",G18="CE"),O18="Simples"),3, IF(AND(OR(G18="EE",G18="CE"),O18="Médio"),4, IF(AND(OR(G18="EE",G18="CE"),O18="Complexo"),6, IF(AND(G18="SE",O18="Simples"),4, IF(AND(G18="SE",O18="Médio"),5, IF(AND(G18="SE",O18="Complexo"),7,0)))))) -> 3 | Q18: =IF(AND(G18="ALI",N18="Simples"),7, IF(AND(G18="ALI",N18="Médio"),10, IF(AND(G18="ALI",N18="Complexo"),15, IF(AND(G18="AIE",N18="Simples"),5, IF(AND(G18="AIE",N18="Médio"),7, IF(AND(G18="AIE",N18="Complexo"),10,0)))))) -> 0 | R18: =IF(G18="INM",C18*H18,IF(AND(OR(G18="EE",G18="CE"),O18="Simples"),3, IF(AND(OR(G18="EE",G18="CE"),O18="Médio"),4, IF(AND(OR(G18="EE",G18="CE"),O18="Complexo"),6, IF(AND(G18="SE",O18="Simples"),4, IF(AND(G18="SE",O18="Médio"),5, IF(AND(G18="SE",O18="Complexo"),7, IF(AND(G18="ALI",O18="Médio"),10, IF(AND(G18="ALI",O18="Simples"),7, IF(AND(G18="ALI",O18="Complexo"),15, IF(AND(G18="AIE",O18="Simples"),5, IF(AND(G18="AIE",O18="Médio"),7, IF(AND(G18="AIE",O18="Complexo"),10,0)) ))))))))))) -> 3 | S18: =IF(G18="INM",C18*H18,IF(B18<>"Manutenção em interface",IF(B18<>"Desenv., Manutenção e Publicação de Páginas Estáticas",(P18+Q18)*C18,C18),C18)) -> 3 | T18: PDTIC25093-16 | Y18: =IF(X18<>"",VLOOKUP(X18,'Tipo Projeto'!$A$3:$B$44,2,0),0) -> 0 | AE18: =IF(Z18="EE",IF(OR(AND(OR(AC18=1,AC18=0),AA18>0,AA18<5),AND(OR(AC18=1,AC18=0),AA18>4,AA18<16),AND(AC18=2,AA18>0,AA18<5)),"Simples",IF(OR(AND(OR(AC18=1,AC18=0),AA18>15),AND(AC18=2,AA18>4,AA18<16),AND(AC18>2,AA18>0,AA18<5)),"Médio",IF(OR(AND(AC18=2,AA18>15),AND(AC18>2,AA18>4,AA18<16),AND(AC18>2,AA18>15)),"Complexo",""))), IF(OR(Z18="CE",Z18="SE"),IF(OR(AND(OR(AC18=1,AC18=0),AA18>0,AA18<6),AND(OR(AC18=1,AC18=0),AA18>5,AA18<20),AND(AC18>1,AC18<4,AA18>0,AA18<6)),"Simples",IF(OR(AND(OR(AC18=1,AC18=0),AA18>19),AND(AC18>1,AC18<4,AA18>5,AA18<20),AND(AC18>3,AA18>0,AA18<6)),"Médio",IF(OR(AND(AC18>1,AC18<4,AA18>19),AND(AC18>3,AA18>5,AA18<20),AND(AC18>3,AA18>19)),"Complexo",""))),"")) | AF18: =IF(Z18="ALI",IF(OR(AND(OR(AC18=1,AC18=0),AA18>0,AA18<20),AND(OR(AC18=1,AC18=0),AA18>19,AA18<51),AND(AC18>1,AC18<6,AA18>0,AA18<20)),"Simples",IF(OR(AND(OR(AC18=1,AC18=0),AA18>50),AND(AC18>1,AC18<6,AA18>19,AA18<51),AND(AC18>5,AA18>0,AA18<20)),"Médio",IF(OR(AND(AC18>1,AC18<6,AA18>50),AND(AC18>5,AA18>19,AA18<51),AND(AC18>5,AA18>50)),"Complexo",""))), IF(Z18="AIE",IF(OR(AND(OR(AC18=1, AC18=0),AA18>0,AA18<20),AND(OR(AC18=1, AC18=0),AA18>19,AA18<51),AND(AC18>1,AC18<6,AA18>0,AA18<20)),"Simples",IF(OR(AND(OR(AC18=1, AC18=0),AA18>50),AND(AC18>1,AC18<6,AA18>19,AA18<51),AND(AC18>5,AA18>0,AA18<20)),"Médio",IF(OR(AND(AC18>1,AC18<6,AA18>50),AND(AC18>5,AA18>19,AA18<51),AND(AC18>5,AA18>50)),"Complexo",""))),"")) | AG18: =IF(AE18="",AF18,IF(AF18="",AE18,"")) | AH18: =IF(AND(OR(Z18="EE",Z18="CE"),AG18="Simples"),3, IF(AND(OR(Z18="EE",Z18="CE"),AG18="Médio"),4, IF(AND(OR(Z18="EE",Z18="CE"),AG18="Complexo"),6, IF(AND(Z18="SE",AG18="Simples"),4, IF(AND(Z18="SE",AG18="Médio"),5, IF(AND(Z18="SE",AG18="Complexo"),7,0)))))) -> 0 | AI18: =IF(AND(Z18="ALI",AF18="Simples"),7, IF(AND(Z18="ALI",AF18="Médio"),10, IF(AND(Z18="ALI",AF18="Complexo"),15, IF(AND(Z18="AIE",AF18="Simples"),5, IF(AND(Z18="AIE",AF18="Médio"),7, IF(AND(Z18="AIE",AF18="Complexo"),10,0)))))) -> 0 | AJ18: =IF(W18="OK",S18,( IF(X18<>"Manutenção em interface",IF(X18<>"Desenv., Manutenção e Publicação de Páginas Estáticas",(AH18+AI18)*Y18,Y18),Y18))) -> 0 | AP18: =IF(AJ18=0,"",IF(AJ18=S18,"OK","Divergente"))
B19: Guia de Métricas da STI - Aplicação/Desenvolvimento | C19: =IF(B19<>"",VLOOKUP(B19,'Tipo Projeto'!$A$3:$B$44,2,0),0) -> 1 | D19: Categoria | F19: Detalhar Categoria | G19: SE | M19: =IF(G19="EE",IF(OR(AND(OR(K19=1,K19=0),I19>0,I19<5),AND(OR(K19=1,K19=0),I19>4,I19<16),AND(K19=2,I19>0,I19<5)),"Simples",IF(OR(AND(OR(K19=1,K19=0),I19>15),AND(K19=2,I19>4,I19<16),AND(K19>2,I19>0,I19<5)),"Médio",IF(OR(AND(K19=2,I19>15),AND(K19>2,I19>4,I19<16),AND(K19>2,I19>15)),"Complexo",""))), IF(OR(G19="CE",G19="SE"),IF(OR(AND(OR(K19=1,K19=0),I19>0,I19<6),AND(OR(K19=1,K19=0),I19>5,I19<20),AND(K19>1,K19<4,I19>0,I19<6)),"Simples",IF(OR(AND(OR(K19=1,K19=0),I19>19),AND(K19>1,K19<4,I19>5,I19<20),AND(K19>3,I19>0,I19<6)),"Médio",IF(OR(AND(K19>1,K19<4,I19>19),AND(K19>3,I19>5,I19<20),AND(K19>3,I19>19)),"Complexo",""))),"")) | N19: =IF(G19="ALI",IF(OR(AND(OR(K19=1,K19=0),I19>0,I19<20),AND(OR(K19=1,K19=0),I19>19,I19<51),AND(K19>1,K19<6,I19>0,I19<20)),"Simples",IF(OR(AND(OR(K19=1,K19=0),I19>50),AND(K19>1,K19<6,I19>19,I19<51),AND(K19>5,I19>0,I19<20)),"Médio",IF(OR(AND(K19>1,K19<6,I19>50),AND(K19>5,I19>19,I19<51),AND(K19>5,I19>50)),"Complexo",""))), IF(G19="AIE",IF(OR(AND(OR(K19=1, K19=0),I19>0,I19<20),AND(OR(K19=1, K19=0),I19>19,I19<51),AND(K19>1,K19<6,I19>0,I19<20)),"Simples",IF(OR(AND(OR(K19=1, K19=0),I19>50),AND(K19>1,K19<6,I19>19,I19<51),AND(K19>5,I19>0,I19<20)),"Médio",IF(OR(AND(K19>1,K19<6,I19>50),AND(K19>5,I19>19,I19<51),AND(K19>5,I19>50)),"Complexo",""))),"")) | O19: =IF(M19="",N19,IF(N19="",M19,"")) | P19: =IF(AND(OR(G19="EE",G19="CE"),O19="Simples"),3, IF(AND(OR(G19="EE",G19="CE"),O19="Médio"),4, IF(AND(OR(G19="EE",G19="CE"),O19="Complexo"),6, IF(AND(G19="SE",O19="Simples"),4, IF(AND(G19="SE",O19="Médio"),5, IF(AND(G19="SE",O19="Complexo"),7,0)))))) -> 0 | Q19: =IF(AND(G19="ALI",N19="Simples"),7, IF(AND(G19="ALI",N19="Médio"),10, IF(AND(G19="ALI",N19="Complexo"),15, IF(AND(G19="AIE",N19="Simples"),5, IF(AND(G19="AIE",N19="Médio"),7, IF(AND(G19="AIE",N19="Complexo"),10,0)))))) -> 0 | R19: =IF(G19="INM",C19*H19,IF(AND(OR(G19="EE",G19="CE"),O19="Simples"),3, IF(AND(OR(G19="EE",G19="CE"),O19="Médio"),4, IF(AND(OR(G19="EE",G19="CE"),O19="Complexo"),6, IF(AND(G19="SE",O19="Simples"),4, IF(AND(G19="SE",O19="Médio"),5, IF(AND(G19="SE",O19="Complexo"),7, IF(AND(G19="ALI",O19="Médio"),10, IF(AND(G19="ALI",O19="Simples"),7, IF(AND(G19="ALI",O19="Complexo"),15, IF(AND(G19="AIE",O19="Simples"),5, IF(AND(G19="AIE",O19="Médio"),7, IF(AND(G19="AIE",O19="Complexo"),10,0)) ))))))))))) -> 0 | S19: =IF(G19="INM",C19*H19,IF(B19<>"Manutenção em interface",IF(B19<>"Desenv., Manutenção e Publicação de Páginas Estáticas",(P19+Q19)*C19,C19),C19)) -> 0 | T19: PDTIC25093-16 | U19: Mesmo PE que o Consultar Categoria (implícita) | Y19: =IF(X19<>"",VLOOKUP(X19,'Tipo Projeto'!$A$3:$B$44,2,0),0) -> 0 | AE19: =IF(Z19="EE",IF(OR(AND(OR(AC19=1,AC19=0),AA19>0,AA19<5),AND(OR(AC19=1,AC19=0),AA19>4,AA19<16),AND(AC19=2,AA19>0,AA19<5)),"Simples",IF(OR(AND(OR(AC19=1,AC19=0),AA19>15),AND(AC19=2,AA19>4,AA19<16),AND(AC19>2,AA19>0,AA19<5)),"Médio",IF(OR(AND(AC19=2,AA19>15),AND(AC19>2,AA19>4,AA19<16),AND(AC19>2,AA19>15)),"Complexo",""))), IF(OR(Z19="CE",Z19="SE"),IF(OR(AND(OR(AC19=1,AC19=0),AA19>0,AA19<6),AND(OR(AC19=1,AC19=0),AA19>5,AA19<20),AND(AC19>1,AC19<4,AA19>0,AA19<6)),"Simples",IF(OR(AND(OR(AC19=1,AC19=0),AA19>19),AND(AC19>1,AC19<4,AA19>5,AA19<20),AND(AC19>3,AA19>0,AA19<6)),"Médio",IF(OR(AND(AC19>1,AC19<4,AA19>19),AND(AC19>3,AA19>5,AA19<20),AND(AC19>3,AA19>19)),"Complexo",""))),"")) | AF19: =IF(Z19="ALI",IF(OR(AND(OR(AC19=1,AC19=0),AA19>0,AA19<20),AND(OR(AC19=1,AC19=0),AA19>19,AA19<51),AND(AC19>1,AC19<6,AA19>0,AA19<20)),"Simples",IF(OR(AND(OR(AC19=1,AC19=0),AA19>50),AND(AC19>1,AC19<6,AA19>19,AA19<51),AND(AC19>5,AA19>0,AA19<20)),"Médio",IF(OR(AND(AC19>1,AC19<6,AA19>50),AND(AC19>5,AA19>19,AA19<51),AND(AC19>5,AA19>50)),"Complexo",""))), IF(Z19="AIE",IF(OR(AND(OR(AC19=1, AC19=0),AA19>0,AA19<20),AND(OR(AC19=1, AC19=0),AA19>19,AA19<51),AND(AC19>1,AC19<6,AA19>0,AA19<20)),"Simples",IF(OR(AND(OR(AC19=1, AC19=0),AA19>50),AND(AC19>1,AC19<6,AA19>19,AA19<51),AND(AC19>5,AA19>0,AA19<20)),"Médio",IF(OR(AND(AC19>1,AC19<6,AA19>50),AND(AC19>5,AA19>19,AA19<51),AND(AC19>5,AA19>50)),"Complexo",""))),"")) | AG19: =IF(AE19="",AF19,IF(AF19="",AE19,"")) | AH19: =IF(AND(OR(Z19="EE",Z19="CE"),AG19="Simples"),3, IF(AND(OR(Z19="EE",Z19="CE"),AG19="Médio"),4, IF(AND(OR(Z19="EE",Z19="CE"),AG19="Complexo"),6, IF(AND(Z19="SE",AG19="Simples"),4, IF(AND(Z19="SE",AG19="Médio"),5, IF(AND(Z19="SE",AG19="Complexo"),7,0)))))) -> 0 | AI19: =IF(AND(Z19="ALI",AF19="Simples"),7, IF(AND(Z19="ALI",AF19="Médio"),10, IF(AND(Z19="ALI",AF19="Complexo"),15, IF(AND(Z19="AIE",AF19="Simples"),5, IF(AND(Z19="AIE",AF19="Médio"),7, IF(AND(Z19="AIE",AF19="Complexo"),10,0)))))) -> 0 | AJ19: =IF(W19="OK",S19,( IF(X19<>"Manutenção em interface",IF(X19<>"Desenv., Manutenção e Publicação de Páginas Estáticas",(AH19+AI19)*Y19,Y19),Y19))) -> 0 | AP19: =IF(AJ19=0,"",IF(AJ19=S19,"OK","Divergente"))
